Workbook
Name Slicer_City: #N/A
Name Slicer_Industry: #N/A
Name Slicer_Lead_Status: #N/A
Name Slicer_Priority: #N/A
Name Slicer_Product: #N/A
Name Slicer_Product1: #N/A
Name Slicer_Salesperson: #N/A
Name Slicer_Source: #N/A
Name Slicer_Stage: #N/A
Name Slicer_Stage1: #N/A
Name Slicer_Status: #N/A

Sheet Customers
A1: Customer ID | B1: Customer Name | C1: Company | D1: Industry | E1: Email | F1: Phone | G1: City | H1: Salesperson
A2: ="C"&TEXT(ROW()-1,"000") -> C001 | B2: Rahul Sharma | C2: ABC Pvt Ltd | D2: IT Services | E2: rahul.sharma@gmail.com | F2: 7295065228 | G2: Gurgaon | H2: Karan
A3: ="C"&TEXT(ROW()-1,"000") -> C002 | B3: Priya Patel | C3: XYZ Ltd | D3: Retail | E3: priya.patel@gmail.com | F3: 8128294463 | G3: Chennai | H3: Neha
A4: ="C"&TEXT(ROW()-1,"000") -> C003 | B4: John Thomas | C4: Infosys | D4: IT Services | E4: john.thomas@gmail.com | F4: 6569394081 | G4: Noida | H4: Ankit
A5: ="C"&TEXT(ROW()-1,"000") -> C004 | B5: Sneha Reddy | C5: TCS | D5: IT Services | E5: sneha.reddy@gmail.com | F5: 9316165576 | G5: Pune | H5: Sneha
A6: ="C"&TEXT(ROW()-1,"000") -> C005 | B6: Arjun Kumar | C6: Wipro | D6: IT Services | E6: arjun.kumar@gmail.com | F6: 7100393433 | G6: Pune | H6: Priya
A7: ="C"&TEXT(ROW()-1,"000") -> C006 | B7: Ananya Singh | C7: Flipkart | D7: IT Services | E7: ananya.singh@gmail.com | F7: 8360506364 | G7: Chennai | H7: Priya
A8: ="C"&TEXT(ROW()-1,"000") -> C007 | B8: Rohit Verma | C8: Amazon | D8: IT Services | E8: rohit.verma@gmail.com | F8: 6836918603 | G8: Gurgaon | H8: Ankit
A9: ="C"&TEXT(ROW()-1,"000") -> C008 | B9: Kiran Rao | C9: Reliance Industries | D9: IT Services | E9: kiran.rao@gmail.com | F9: 7160353236 | G9: Kolkata | H9: Rahul
A10: ="C"&TEXT(ROW()-1,"000") -> C009 | B10: Aisha Khan | C10: HCL Technologies | D10: Consulting | E10: aisha.khan@gmail.com | F10: 7358677103 | G10: Noida | H10: Ankit
A11: ="C"&TEXT(ROW()-1,"000") -> C010 | B11: Vikram Mehta | C11: Capgemini | D11: Consulting | E11: vikram.mehta@gmail.com | F11: 8201181881 | G11: Chennai | H11: Karan
A12: ="C"&TEXT(ROW()-1,"000") -> C011 | B12: Deepak Nair | C12: Accenture | D12: Technology | E12: deepak.nair@gmail.com | F12: 8980385975 | G12: Kolkata | H12: Karan
A13: ="C"&TEXT(ROW()-1,"000") -> C012 | B13: Pooja Shah | C13: Cognizant | D13: Technology | E13: pooja.shah@gmail.com | F13: 8564693392 | G13: Delhi | H13: Karan
... A41: ="C"&TEXT(ROW()-1,"000") -> C040 | B41: Pavan Kumar | C41: Spark Technologies | D41: Semiconductors | E41: pavan.kumar@gmail.com | F41: 8307798168 | G41: Ahmedabad | H41: Ankit

Sheet Leads
A1: Lead ID | B1: Customer ID | C1: Lead Status | D1: Source | E1: Expected Revenue | F1: Priority | G1: Created Date
A2: L001 | B2: C037 | C2: Contacted | D2: Website | E2: 787444 | F2: Medium | G2: 46201
A3: L002 | B3: C025 | C3: Qualified | D3: Email | E3: 709978 | F3: High | G3: 46246
A4: L003 | B4: C032 | C4: Contacted | D4: LinkedIn | E4: 783705 | F4: Low | G4: 46091
A5: L004 | B5: C004 | C5: New | D5: Email | E5: 414696 | F5: Medium | G5: 46135
A6: L005 | B6: C001 | C6: Lost | D6: Email | E6: 954597 | F6: Low | G6: 46274
A7: L006 | B7: C025 | C7: Proposal Sent | D7: Email | E7: 764936 | F7: Low | G7: 46033
A8: L007 | B8: C018 | C8: Contacted | D8: Referral | E8: 154903 | F8: Medium | G8: 46270
A9: L008 | B9: C013 | C9: Lost | D9: Cold Call | E9: 410356 | F9: Low | G9: 46341
A10: L009 | B10: C030 | C10: Lost | D10: Cold Call | E10: 260515 | F10: High | G10: 46191
A11: L010 | B11: C011 | C11: Won | D11: Referral | E11: 524252 | F11: Low | G11: 46224
A12: L011 | B12: C032 | C12: Proposal Sent | D12: Referral | E12: 641217 | F12: Low | G12: 46185
A13: L012 | B13: C040 | C13: Lost | D13: Referral | E13: 179377 | F13: Medium | G13: 46183
... A51: L050 | B51: C036 | C51: New | D51: Email | E51: 66535 | F51: Low | G51: 46236

Sheet Opportunities
A1: Opportunity ID | B1: Customer ID | C1: Product | D1: Amount | E1: Probability (%) | F1: Closing Date | G1: Stage
A2: O001 | B2: C028 | C2: AI Chatbot | D2: 1977740 | E2: 90 | F2: 46067 | G2: Prospecting
A3: O002 | B3: C008 | C3: Data Analytics | D3: 1266357 | E3: 48 | F3: 46260 | G3: Closed Lost
A4: O003 | B4: C010 | C4: Cyber Security | D4: 1788799 | E4: 98 | F4: 46322 | G4: Closed Won
A5: O004 | B5: C040 | C5: HRMS | D5: 1078589 | E5: 55 | F5: 46351 | G5: Prospecting
A6: O005 | B6: C025 | C6: HRMS | D6: 956441 | E6: 79 | F6: 46065 | G6: Negotiation
A7: O006 | B7: C022 | C7: Cyber Security | D7: 1929739 | E7: 17 | F7: 46056 | G7: Proposal
A8: O007 | B8: C018 | C8: HRMS | D8: 784172 | E8: 58 | F8: 46085 | G8: Closed Lost
A9: O008 | B9: C024 | C9: Data Analytics | D9: 796882 | E9: 34 | F9: 46376 | G9: Proposal
A10: O009 | B10: C006 | C10: Data Analytics | D10: 507200 | E10: 29 | F10: 46144 | G10: Proposal
A11: O010 | B11: C032 | C11: HRMS | D11: 1964869 | E11: 92 | F11: 46226 | G11: Prospecting
A12: O011 | B12: C013 | C12: Cloud Hosting | D12: 518405 | E12: 82 | F12: 46344 | G12: Closed Lost
A13: O012 | B13: C023 | C13: Data Analytics | D13: 1303718 | E13: 76 | F13: 46272 | G13: Closed Lost
... A31: O030 | B31: C001 | C31: HRMS | D31: 1579990 | E31: 90 | F31: 46327 | G31: Prospecting

Sheet Follow-ups
A1: Follow-Up ID | B1: Customer ID | C1: Follow-Up Date | D1: Next Follow-Up | E1: Notes | F1: Status
A2: F001 | B2: C011 | C2: 46349 | D2: 46356 | E2: Follow-up Required | F2: Completed
A3: F002 | B3: C014 | C3: 46080 | D3: 46087 | E3: Waiting for Response | F3: Pending
A4: F003 | B4: C037 | C4: 46338 | D4: 46344 | E4: Demo Completed | F4: Cancelled
A5: F004 | B5: C017 | C5: 46306 | D5: 46317 | E5: Client Requested Callback | F5: Cancelled
A6: F005 | B6: C019 | C6: 46048 | D6: 46057 | E6: Email Sent | F6: Completed
A7: F006 | B7: C020 | C7: 46054 | D7: 46069 | E7: Meeting Scheduled | F7: Cancelled
A8: F007 | B8: C036 | C8: 46206 | D8: 46215 | E8: Waiting for Response | F8: Cancelled
A9: F008 | B9: C015 | C9: 46253 | D9: 46257 | E9: Follow-up Required | F9: Completed
A10: F009 | B10: C040 | C10: 46370 | D10: 46379 | E10: Demo Completed | F10: Completed
A11: F010 | B11: C036 | C11: 46221 | D11: 46224 | E11: Email Sent | F11: Completed
A12: F011 | B12: C022 | C12: 46341 | D12: 46353 | E12: Demo Completed | F12: Completed
A13: F012 | B13: C021 | C13: 46258 | D13: 46262 | E13: Call Scheduled | F13: Cancelled
... A26: F025 | B26: C019 | C26: 46039 | D26: 46053 | E26: Proposal Shared | F26: Completed

Sheet Dashboard
A1: CRM Dashboard
A4: Total Customers | E4: Total Leads | I4: Total Opportunities
A5: =COUNTA(Customers!A2:A41) -> 40 | E5: =COUNTA(Leads!A2:A51) -> 50 | I5: =COUNTA(Opportunities!A2:A31) -> 30
A8: Total Follow-Ups | E8: Total Revenue | I8: Avg Deal Size
A9: =COUNTA('Follow-ups'!A2:A26) -> 25 | E9: =SUM(Opportunities!D2:D31) -> 37779954 | I9: =AVERAGE(Opportunities!D2:D31) -> 1259331.8
A13: Row Labels | B13: Count of Lead ID
A14: Contacted | B14: 10
A15: Lost | B15: 9
A16: Negotiation | B16: 7
A17: New | B17: 3
A18: Proposal Sent | B18: 7
A19: Qualified | B19: 8
A20: Won | B20: 6
A21: Grand Total | B21: 50
A26: Row Labels | B26: Sum of Amount
A27: AI Chatbot | B27: 3709234
A28: Cloud Hosting | B28: 2732457
A29: CRM Software | B29: 5360620
A30: Cyber Security | B30: 3718538
A31: Data Analytics | B31: 3874157
A32: ERP System | B32: 4414265
A33: HRMS | B33: 10571867
A34: Inventory System | B34: 3398816
A35: Grand Total | B35: 37779954
A44: Row Labels | B44: Count of Opportunity ID
A45: Closed Lost | B45: 8
A46: Closed Won | B46: 2
A47: Negotiation | B47: 4
A48: Proposal | B48: 7
A49: Prospecting | B49: 9
A50: Grand Total | B50: 30
A58: Row Labels | B58: Count of Customer ID
A59: Ahmedabad | B59: 6
A60: Bangalore | B60: 4
A61: Chennai | B61: 4
A62: Delhi | B62: 4
A63: Gurgaon | B63: 7
A64: Kolkata | B64: 6
A65: Mumbai | B65: 1
A66: Noida | B66: 4
...
